unload bsc/commands (PATH, MANPATH) 
unload CUDA/9.1 (PATH, MANPATH, LD_LIBRARY_PATH, LIBRARY_PATH, C_INCLUDE_PATH,
CPLUS_INCLUDE_PATH, CUDA_HOME, CUDA_VERSION, CUDA_INC, CUDA_INSTALL_PATH) 
unload OPENMPI/3.0.0 (PATH, MANPATH, LD_LIBRARY_PATH, LIBRARY_PATH,
PKG_CONFIG_PATH, C_INCLUDE_PATH, CPLUS_INCLUDE_PATH, MPI, MPI_V) 
unload GCC/6.4.0 (PATH, MANPATH, INFOPATH, LD_LIBRARY_PATH, LIBRARY_PATH,
C_INCLUDE_PATH, CPLUS_INCLUDE_PATH, STD COMP VARS) 
load GCC/8.3.0 (PATH, MANPATH, INFOPATH, LIBRARY_PATH, LD_LIBRARY_PATH, STD
COMP VARS) 
load FFMPEG/4.2.1 (PATH, LIBRARY_PATH, PKG_CONFIG_PATH, C_INCLUDE_PATH,
CPLUS_INCLUDE_PATH) 
load CUDA/10.2 (PATH, MANPATH, LD_LIBRARY_PATH, LIBRARY_PATH, C_INCLUDE_PATH,
CPLUS_INCLUDE_PATH, CUDA_HOME, CUDA_VERSION, CUDA_INC, CUDA_INSTALL_PATH) 
load CUDNN/7.6.4 (LD_LIBRARY_PATH, LIBRARY_PATH, C_INCLUDE_PATH,
CPLUS_INCLUDE_PATH, CUDNN_LIB_DIR, CUDNN_LIBRARY, CUDNN_INCLUDE_DIR) 
load NCCL/2.4.8 (LD_LIBRARY_PATH, LIBRARY_PATH, C_INCLUDE_PATH,
CPLUS_INCLUDE_PATH) 
load TENSORRT/6.0.1 (PATH, LD_LIBRARY_PATH, LIBRARY_PATH, C_INCLUDE_PATH,
CPLUS_INCLUDE_PATH) 
load OPENMPI/4.0.1 (PATH, MANPATH, LD_LIBRARY_PATH, LIBRARY_PATH,
PKG_CONFIG_PATH, C_INCLUDE_PATH, CPLUS_INCLUDE_PATH, MPI, MPI_V) 
load ATLAS/3.10.3 (LD_LIBRARY_PATH, LIBRARY_PATH, C_INCLUDE_PATH,
CPLUS_INCLUDE_PATH) 
load SCALAPACK/2.0.2 (LD_LIBRARY_PATH, LIBRARY_PATH, PKG_CONFIG_PATH) 
load FFTW/3.3.8 (PATH, MANPATH, LD_LIBRARY_PATH, LIBRARY_PATH, C_INCLUDE_PATH,
CPLUS_INCLUDE_PATH, PKG_CONFIG_PATH) 
load SZIP/2.1.1 (LD_LIBRARY_PATH, LIBRARY_PATH, C_INCLUDE_PATH,
CPLUS_INCLUDE_PATH) 
load OPENCV/4.1.1 (PATH, LD_LIBRARY_PATH, LIBRARY_PATH, C_INCLUDE_PATH,
CPLUS_INCLUDE_PATH, PYTHONPATH) 
load PYTHON/3.7.4_ML (PATH, MANPATH, LD_LIBRARY_PATH, LIBRARY_PATH,
PKG_CONFIG_PATH, C_INCLUDE_PATH, CPLUS_INCLUDE_PATH, PYTHONHOME, PYTHONPATH,
OMPI_MCA_mpi_warn_on_fork, PROTOCOL_BUFFERS_PYTHON_IMPLEMENTATION,
PROTOCOL_BUFFERS_PYTHON_IMPLEMENTATION_VERSION) 
2023-11-20 14:18:05.854322: I tensorflow/stream_executor/platform/default/dso_loader.cc:48] Successfully opened dynamic library libcudart.so.10.2
2023-11-20 14:18:25.504583: I tensorflow/stream_executor/platform/default/dso_loader.cc:48] Successfully opened dynamic library libcuda.so.1
2023-11-20 14:18:25.549607: I tensorflow/core/common_runtime/gpu/gpu_device.cc:1716] Found device 0 with properties: 
pciBusID: 0035:03:00.0 name: Tesla V100-SXM2-16GB computeCapability: 7.0
coreClock: 1.53GHz coreCount: 80 deviceMemorySize: 15.75GiB deviceMemoryBandwidth: 836.37GiB/s
2023-11-20 14:18:25.549655: I tensorflow/stream_executor/platform/default/dso_loader.cc:48] Successfully opened dynamic library libcudart.so.10.2
2023-11-20 14:18:25.551560: I tensorflow/stream_executor/platform/default/dso_loader.cc:48] Successfully opened dynamic library libcublas.so.10
2023-11-20 14:18:25.553143: I tensorflow/stream_executor/platform/default/dso_loader.cc:48] Successfully opened dynamic library libcufft.so.10
2023-11-20 14:18:25.553626: I tensorflow/stream_executor/platform/default/dso_loader.cc:48] Successfully opened dynamic library libcurand.so.10
2023-11-20 14:18:25.555395: I tensorflow/stream_executor/platform/default/dso_loader.cc:48] Successfully opened dynamic library libcusolver.so.10
2023-11-20 14:18:25.556630: I tensorflow/stream_executor/platform/default/dso_loader.cc:48] Successfully opened dynamic library libcusparse.so.10
2023-11-20 14:18:25.560365: I tensorflow/stream_executor/platform/default/dso_loader.cc:48] Successfully opened dynamic library libcudnn.so.7
2023-11-20 14:18:25.562867: I tensorflow/core/common_runtime/gpu/gpu_device.cc:1858] Adding visible gpu devices: 0
2023-11-20 14:18:25.596049: I tensorflow/core/platform/profile_utils/cpu_utils.cc:104] CPU Frequency: 3783000000 Hz
2023-11-20 14:18:25.597776: I tensorflow/compiler/xla/service/service.cc:168] XLA service 0x2f8a5fd0 initialized for platform Host (this does not guarantee that XLA will be used). Devices:
2023-11-20 14:18:25.597844: I tensorflow/compiler/xla/service/service.cc:176]   StreamExecutor device (0): Host, Default Version
2023-11-20 14:18:25.705224: I tensorflow/compiler/xla/service/service.cc:168] XLA service 0x2f912670 initialized for platform CUDA (this does not guarantee that XLA will be used). Devices:
2023-11-20 14:18:25.705327: I tensorflow/compiler/xla/service/service.cc:176]   StreamExecutor device (0): Tesla V100-SXM2-16GB, Compute Capability 7.0
2023-11-20 14:18:25.708325: I tensorflow/core/common_runtime/gpu/gpu_device.cc:1716] Found device 0 with properties: 
pciBusID: 0035:03:00.0 name: Tesla V100-SXM2-16GB computeCapability: 7.0
coreClock: 1.53GHz coreCount: 80 deviceMemorySize: 15.75GiB deviceMemoryBandwidth: 836.37GiB/s
2023-11-20 14:18:25.708373: I tensorflow/stream_executor/platform/default/dso_loader.cc:48] Successfully opened dynamic library libcudart.so.10.2
2023-11-20 14:18:25.708407: I tensorflow/stream_executor/platform/default/dso_loader.cc:48] Successfully opened dynamic library libcublas.so.10
2023-11-20 14:18:25.708435: I tensorflow/stream_executor/platform/default/dso_loader.cc:48] Successfully opened dynamic library libcufft.so.10
2023-11-20 14:18:25.708463: I tensorflow/stream_executor/platform/default/dso_loader.cc:48] Successfully opened dynamic library libcurand.so.10
2023-11-20 14:18:25.708491: I tensorflow/stream_executor/platform/default/dso_loader.cc:48] Successfully opened dynamic library libcusolver.so.10
2023-11-20 14:18:25.708518: I tensorflow/stream_executor/platform/default/dso_loader.cc:48] Successfully opened dynamic library libcusparse.so.10
2023-11-20 14:18:25.708545: I tensorflow/stream_executor/platform/default/dso_loader.cc:48] Successfully opened dynamic library libcudnn.so.7
2023-11-20 14:18:25.711051: I tensorflow/core/common_runtime/gpu/gpu_device.cc:1858] Adding visible gpu devices: 0
2023-11-20 14:18:25.711103: I tensorflow/stream_executor/platform/default/dso_loader.cc:48] Successfully opened dynamic library libcudart.so.10.2
2023-11-20 14:18:26.454015: I tensorflow/core/common_runtime/gpu/gpu_device.cc:1257] Device interconnect StreamExecutor with strength 1 edge matrix:
2023-11-20 14:18:26.454102: I tensorflow/core/common_runtime/gpu/gpu_device.cc:1263]      0 
2023-11-20 14:18:26.454117: I tensorflow/core/common_runtime/gpu/gpu_device.cc:1276] 0:   N 
2023-11-20 14:18:26.459298: I tensorflow/core/common_runtime/gpu/gpu_device.cc:1402] Created TensorFlow device (/job:localhost/replica:0/task:0/device:GPU:0 with 14728 MB memory) -> physical GPU (device: 0, name: Tesla V100-SXM2-16GB, pci bus id: 0035:03:00.0, compute capability: 7.0)
Traceback (most recent call last):
  File "/apps/PYTHON/3.7.4_ML/lib/python3.7/urllib/request.py", line 1317, in do_open
    encode_chunked=req.has_header('Transfer-encoding'))
  File "/apps/PYTHON/3.7.4_ML/lib/python3.7/http/client.py", line 1244, in request
    self._send_request(method, url, body, headers, encode_chunked)
  File "/apps/PYTHON/3.7.4_ML/lib/python3.7/http/client.py", line 1290, in _send_request
    self.endheaders(body, encode_chunked=encode_chunked)
  File "/apps/PYTHON/3.7.4_ML/lib/python3.7/http/client.py", line 1239, in endheaders
    self._send_output(message_body, encode_chunked=encode_chunked)
  File "/apps/PYTHON/3.7.4_ML/lib/python3.7/http/client.py", line 1026, in _send_output
    self.send(msg)
  File "/apps/PYTHON/3.7.4_ML/lib/python3.7/http/client.py", line 966, in send
    self.connect()
  File "/apps/PYTHON/3.7.4_ML/lib/python3.7/http/client.py", line 1406, in connect
    super().connect()
  File "/apps/PYTHON/3.7.4_ML/lib/python3.7/http/client.py", line 938, in connect
    (self.host,self.port), self.timeout, self.source_address)
  File "/apps/PYTHON/3.7.4_ML/lib/python3.7/socket.py", line 727, in create_connection
    raise err
  File "/apps/PYTHON/3.7.4_ML/lib/python3.7/socket.py", line 716, in create_connection
    sock.connect(sa)
OSError: [Errno 101] Network is unreachable

During handling of the above exception, another exception occurred:

Traceback (most recent call last):
  File "/apps/PYTHON/3.7.4_ML/lib/python3.7/site-packages/tensorflow/python/keras/utils/data_utils.py", line 278, in get_file
    urlretrieve(origin, fpath, dl_progress)
  File "/apps/PYTHON/3.7.4_ML/lib/python3.7/urllib/request.py", line 247, in urlretrieve
    with contextlib.closing(urlopen(url, data)) as fp:
  File "/apps/PYTHON/3.7.4_ML/lib/python3.7/urllib/request.py", line 222, in urlopen
    return opener.open(url, data, timeout)
  File "/apps/PYTHON/3.7.4_ML/lib/python3.7/urllib/request.py", line 525, in open
    response = self._open(req, data)
  File "/apps/PYTHON/3.7.4_ML/lib/python3.7/urllib/request.py", line 543, in _open
    '_open', req)
  File "/apps/PYTHON/3.7.4_ML/lib/python3.7/urllib/request.py", line 503, in _call_chain
    result = func(*args)
  File "/apps/PYTHON/3.7.4_ML/lib/python3.7/urllib/request.py", line 1360, in https_open
    context=self._context, check_hostname=self._check_hostname)
  File "/apps/PYTHON/3.7.4_ML/lib/python3.7/urllib/request.py", line 1319, in do_open
    raise URLError(err)
urllib.error.URLError: <urlopen error [Errno 101] Network is unreachable>

During handling of the above exception, another exception occurred:

Traceback (most recent call last):
  File "create_feature_vector.py", line 45, in <module>
    model = VGG16(weights='imagenet', include_top=False, input_shape=(256, 256, 3))  # Set include_top=False to use as a feature extractor
  File "/apps/PYTHON/3.7.4_ML/lib/python3.7/site-packages/tensorflow/python/keras/applications/vgg16.py", line 220, in VGG16
    file_hash='6d6bbae143d832006294945121d1f1fc')
  File "/apps/PYTHON/3.7.4_ML/lib/python3.7/site-packages/tensorflow/python/keras/utils/data_utils.py", line 282, in get_file
    raise Exception(error_msg.format(origin, e.errno, e.reason))
Exception: URL fetch failure on https://storage.googleapis.com/tensorflow/keras-applications/vgg16/vgg16_weights_tf_dim_ordering_tf_kernels_notop.h5: None -- [Errno 101] Network is unreachable
